Workbook

Sheet Validate_2020
B1: Total | C1: Fraction | D1: FAO (2019) estimates --- all catl | E1: FAO (2019) estimates --- beef cattle -- no trend adjustment | F1: FAO (2019) estimates --- beef cattle -- trend adjustment | G1: trend.line(FAO) | H1: Absolute difference
A2: Pastoral | B2: =Herd_decision_tree!E10 -> 8.530191 | C2: =B2/$B$8 -> 0.51509166 | D2: =[1]FAO_2019_animal_trends!$F$35 -> 0.5361596 | E2: =D2/D$8 -> 0.5361596 | F2: =E2-5*G2*E2*0.96/100 -> 0.52629975 | G2: =[1]FAO_2019_animal_trends!$G$35 -> 0.3831201 | H2: =ABS(F2-C2) -> 0.011208095
A3: Agropastoral | B3: =Herd_decision_tree!E14 -> 5.5211887 | C3: =B3/$B$8 -> 0.33339444 | D3: =[1]FAO_2019_animal_trends!$F$36 -> 0.36159601 | E3: =D3/D$8 -> 0.36159601 | F3: =E3-5*G3*E3*0.95/100 -> 0.31358889 | G3: =[1]FAO_2019_animal_trends!$G$36 -> 2.7950424 | H3: =ABS(F3-C3) -> 0.019805549
A4: Mixed | B4: =Herd_decision_tree!E18 -> 0.94977299 | C4: =B4/$B$8 -> 0.057351605 | D4: =[1]FAO_2019_animal_trends!$F$39 -> 0.049875312 | E4: =D4/D$8 -> 0.049875312 | F4: =E4-5*G4*E4*0.95/100 -> 0.046666186 | G4: =[1]FAO_2019_animal_trends!$G$40 -> 1.3545888 | H4: =ABS(F4-C4) -> 0.010685419
A5: Cow-calf | B5: =Herd_decision_tree!E29 -> 0.84378557 | C5: =B5/$B$8 -> 0.050951604 | D5: =[1]FAO_2019_animal_trends!$F$38 -> 0.049875312 | E5: =D5/D$8 -> 0.049875312 | F5: =E5-5*G5*E5*0.95/100 -> 0.047418024 | G5: =[1]FAO_2019_animal_trends!$G$38 -> 1.037234 | H5: =ABS(F5-C5) -> 0.0035335795
A6: Finisher | B6: =Herd_decision_tree!E25 -> 0.71559201 | C6: =B6/$B$8 -> 0.043210695 | D6: =[1]FAO_2019_animal_trends!$F$37 -> 0.0024937656 | E6: =D6/D$8 -> 0.0024937656 | F6: =E6-5*G6*E6*0.95/100 -> -0.0077485333 | G6: =[1]FAO_2019_animal_trends!$G$37 -> 86.466565 | H6: =ABS(F6-C6) -> 0.050959228
A7: Sheep | G7: =76.3/(2012-1978.5) -> 2.2776119
B8: =SUM(B2:B6) -> 16.56053 | D8: =SUM(D2:D6) -> 1 | H8: =SUM(H2:H6) -> 0.09619187

Sheet Herd_decision_tree
B1: Arid | C1: Sarid | D1: Humid | E1: All | G1: Parameters | K1: Sources
A2: Comm beef | B2: =[2]Arid_Subsistence!$C$2/1000000*$H$18 -> 0.2693585 | C2: =[3]SArid_Subsistence!$C$2/1000000*$H$18 -> 0.57058834 | D2: =[4]Humid_Subsistence!$D$2/1000000*$H$18 -> 0.71943075 | E2: =SUM(B2:D2) -> 1.5593776 | G2: Commercial | H2: Frac finisher to total animal population | I2: 0.035 | K2: Gatsby
A3: Subs beef | B3: =[5]Arid_Commercial!$C$2/1000000*$H$18 -> 5.5884479 | C3: =[6]SArid_Commercial!$C$2/1000000*$H$18 -> 7.2365694 | D3: =[7]Humid_Commercial!$D$2/1000000*$H$18 -> 6.0610912 | E3: =SUM(B3:D3) -> 18.886109 | H3: Frac boran to total herd | I3: 0.68 | K3: APRI (2025)
A4: Dairy | B4: =[8]Dairy_total_Arid_2020!$C$2/1000000*$H$18 -> 0.030271362 | C4: =[9]Dairy_total_SArid_2020!$C$2/1000000*$H$18 -> 1.4765741 | D4: =[10]Dairy_total_Humid_2020!$D$2/1000000*$H$18 -> 6.385378
A5: Sheep | B5: =9.78*0.76*[11]Sheep_total_Arid_2020!$C$2/1000000*$H$18 -> 11.794047 | C5: =9.78*0.76*[12]Sheep_total_SArid_2020!$C$2/1000000*$H$18 -> 9.6481198 | D5: =9.78*0.76*[13]Sheep_total_Humid_2020!$D$2/1000000*$H$18 -> 9.0810137 | E5: =SUM(B5:D5) -> 30.523181
A6: Total beef | B6: =SUM(B2:B3) -> 5.8578064 | C6: =SUM(C2:C3) -> 7.8071578 | D6: =SUM(D2:D3) -> 6.7805219 | E6: =SUM(B6:D6) -> 20.445486
G7: Farm decomposition | H7: Frac pastoral to agpastoral - arid | I7: =0.7391304+0.03 -> 0.7691304 | K7: GLS (2019)
A8: Systems | H8: Frac pastoral to agpastoral - semiarid & humid | I8: =0.5348+0.05 -> 0.5848 | K8: GLS (2019)
A9: Subsistence | H9: Frac mixed to agropastoral - semi arid | I9: =0.0567+0.1 -> 0.1567 | K9: GLS (2019)
A10: Pastoral | B10: =B3*I7 -> 4.2982452 | C10: =C3*I8 -> 4.2319458 | E10: =SUM(B10:D10) -> 8.530191
A11: Pastoral - Zebu | B11: =B10*(1-I11) -> 3.7635435 | C11: =C10*(1-I11) -> 3.7054917 | E11: =SUM(B11:D11) -> 7.4690352 | G11: Breed decompositon (by farm-type) | H11: Pastoral -- frac boran to total herd | I11: =(0.1244) -> 0.1244 | K11: GLS (2019)
A12: Pastoral - Boran | B12: =B10*(I11) -> 0.5347017 | C12: =C10*(I11) -> 0.52645406 | E12: =SUM(B12:D12) -> 1.0611558 | H12: Agpastoral -- frac boran to total herd | I12: =(0.07) -> 0.07 | K12: GLS (2019)
H13: Mixed -- Frac boran to total herd | I13: =(0.08) -> 0.08 | K13: GLS (2019)
A14: Agropastoral | C14: =C3*(1-I8) -> 3.0046236 | D14: =D3*(1-I8) -> 2.5165651 | E14: =SUM(B14:D14) -> 5.5211887
A15: Agropastoral - Zebu | C15: =C14*(1-I12) -> 2.7943 | D15: =D14*(1-I12) -> 2.3404055 | E15: =SUM(B15:D15) -> 5.1347055
A16: Agropastoral - Boran | C16: =C14*(I12) -> 0.21032365 | D16: =D14*(I12) -> 0.17615955 | E16: =SUM(B16:D16) -> 0.38648321
A18: Mixed | D18: =D3*I9 -> 0.94977299 | E18: =SUM(B18:D18) -> 0.94977299 | G18: Pixel adjustment | H18: 1.22
A19: Mixed - Zebu | D19: =D$18*(1-I13) -> 0.87379115 | E19: =SUM(B19:D19) -> 0.87379115
A20: Mixed - Boran | D20: =D$18*(I13) -> 0.075981839 | E20: =SUM(B20:D20) -> 0.075981839
A23: Check - subsistence | B23: =SUM(B15:B16)+SUM(B11:B12) -> 4.2982452 | C23: =SUM(C15:C16)+SUM(C11:C12) -> 7.2365694 | D23: =SUM(D15:D16)+SUM(D19:D20) -> 3.4663381 | E23: =SUM(B23:D23) -> 15.001153
A25: Finisher | B25: =B6*$I2 -> 0.20502322 | C25: =C6*$I2 -> 0.27325052 | D25: =D6*$I2 -> 0.23731827 | E25: =SUM(B25:D25) -> 0.71559201
A26: Finisher - Boran | B26: =B25*$I3 -> 0.13941579 | C26: =C25*$I3 -> 0.18581035 | D26: =D25*$I3 -> 0.16137642 | E26: =SUM(B26:D26) -> 0.48660257 | G26: =E26*E49 -> 0.48827648
A27: Finisher - Exotic | B27: =B25*(1-$I3) -> 0.065607432 | C27: =C25*(1-$I3) -> 0.087440167 | D27: =D25*(1-$I3) -> 0.075941846 | E27: =SUM(B27:D27) -> 0.22898944 | G27: =E27*1.21 -> 0.27707723
A29: Cowcalf | B29: =B2-B25 -> 0.064335272 | C29: =C2-C25 -> 0.29733782 | D29: =D2-D25 -> 0.48211248 | E29: =SUM(B29:D29) -> 0.84378557 | G29: =22*E49 -> 22.07568
A30: Cowcalf - Boran | B30: =B29*($I3) -> 0.043747985 | C30: =C29*($I3) -> 0.20218972 | D30: =D29*($I3) -> 0.32783648 | E30: =SUM(B30:D30) -> 0.57377419 | G30: =E30*E49 -> 0.57574796
A31: Cowcalf - Exotic | B31: =B29*(1-$I3) -> 0.020587287 | C31: =C29*(1-$I3) -> 0.095148103 | D31: =D29*(1-$I3) -> 0.15427599 | E31: =SUM(B31:D31) -> 0.27001138
A33: Check - all | B33: =SUM(B11:B12,B15:B16,B26:B27,B30:B31) -> 4.5676037 | C33: =SUM(C11:C12,C15:C16,C26:C27,C30:C31) -> 7.8071578 | D33: =SUM(D11:D12,D15:D16,D30:D31,D19:D20) -> 3.9484505 | E33: =SUM(B33:D33) -> 16.323212
A35: Dairy | B35: =B4 -> 0.030271362 | C35: =C4 -> 1.4765741 | D35: =D4 -> 6.385378 | E35: =SUM(B35:D35) -> 7.8922234
A40: Summary
A41: Breed | H41: CABI (2019) calibration
A42: Zebu | B42: =SUM(B11,B15) -> 3.7635435 | C42: =SUM(C11,C15) -> 6.4997917 | D42: =SUM(D15,D19) -> 3.2141967 | E42: =SUM(B42:D42) -> 13.477532 | F42: =E42/E$46 -> 0.81758575 | H42: Boran | I42: 1.5 | J42: =E43+E44 -> 2.5080157 | K42: =ABS(J42-I42)/J42 -> 0.40191762
A43: Boran -- Subsistence | B43: =SUM(B12,B16) -> 0.5347017 | C43: =SUM(C12,C16) -> 0.73677771 | D43: =SUM(D12,D16) -> 0.17615955 | E43: =SUM(B43:D43) -> 1.447639 | F43: =E43/E$46 -> 0.087817933 | H43: Zebu | I43: =0.95*E48-I42 -> 14.214192 | J43: =E42 -> 13.477532 | K43: =ABS(J43-I43)/J43 -> 0.054658407
A44: Boran -- Commercial | B44: =SUM(B26,B30) -> 0.18316378 | C44: =SUM(C26,C30) -> 0.38800007 | D44: =SUM(D26,D30) -> 0.48921291 | E44: =SUM(B44:D44) -> 1.0603768 | F44: =E44/E$46 -> 0.064325496
A45: Exotic | B45: =SUM(B27,B31) -> 0.086194719 | C45: =SUM(C27,C31) -> 0.18258827 | D45: =SUM(D27,D31) -> 0.23021784 | E45: =SUM(B45:D45) -> 0.49900083 | F45: =E45/E$46 -> 0.030270822
A46: All | B46: =SUM(B42:B45) -> 4.5676037 | C46: =SUM(C42:C45) -> 7.8071578 | D46: =SUM(D42:D45) -> 4.109787 | E46: =SUM(B46:D46) -> 16.484548
E48: =16.541255 -> 16.541255
E49: =E48/E46 -> 1.00344
B52: =B29/B2 -> 0.23884627 | C52: =C29/C2 -> 0.52110742 | D52: =D29/D2 -> 0.67013049
B53: =B25/B2 -> 0.76115373 | C53: =C25/C2 -> 0.47889258 | D53: =D25/D2 -> 0.32986951

Sheet Projections
B1: 2020 | C1: Growth rate | D1: Absolute growth (M hd) | E1: 2050
A2: Pastoral | B2: =Validate_2020!B2*Herd_decision_tree!E49 -> 8.5595347 | C2: =[1]FAO_2019_animal_trends!$G$35/100 -> 0.003831201 | D2: =B2*C2*30 -> 0.98379893 | E2: =B2+D2 -> 9.5433336
A3: Agropastoral | B3: =Validate_2020!B3*Herd_decision_tree!E49 -> 5.5401815 | C3: =[1]FAO_2019_animal_trends!$G36/100 -> 0.027950424 | D3: =B3*C3*30 -> 4.6455127 | E3: =B3+D3 -> 10.185694
A4: Mixed | B4: =Validate_2020!B4*Herd_decision_tree!E49 -> 0.9530402 | C4: =[1]FAO_2019_animal_trends!$G39/100 -> 0.076101824 | D4: =B4*C4*30 -> 2.1758429 | E4: =B4+D4 -> 3.1288831
A5: Cow-calf | B5: =Validate_2020!B5*Herd_decision_tree!E49 -> 0.84668818 | C5: =[1]FAO_2019_animal_trends!$G38/100 -> 0.01037234 | D5: =B5*C5*30 -> 0.26346414 | E5: =B5+D5 -> 1.1101523
A6: Finisher | B6: =Validate_2020!B6*Herd_decision_tree!E49 -> 0.71805364 | C6: =[1]FAO_2019_animal_trends!$G37/100 -> 0.86466565 | D6: =B6*C6*30 -> 18.62629 | E6: =B6+D6 -> 19.344343
A7: Dairy | B7: =Herd_decision_tree!E35 -> 7.8922234 | C7: =[1]FAO_2019_animal_trends!$G39/100 -> 0.076101824 | D7: =B7*C7*30 -> 18.018378 | E7: =B7+D7 -> 25.910601

Sheet ZS_Summary
B1: 2020 | G1: 2050 | L1: Excel method
B2: Breed 1 | C2: Breed 2 | D2: Total | E2: Excel method | G2: Breed 1 | H2: Breed 2 | I2: Total | J2: Delta total | M2: Delta total
A3: Pastoral | B3: =[14]Pastoral_Zebu_2020!$K$2 -> 7912803.6 | C3: =[15]Pastoral_Boran_2020!$K$2 -> 1124203.7 | D3: =SUM(B3:C3)/1000000 -> 9.0370073 | E3: =Herd_decision_tree!E10*Herd_decision_tree!$E$49 -> 8.5595347 | G3: =[16]Pastoral_Zebu_2050!$K$2 -> 8554757.5 | H3: =[17]Pastoral_Boran_2050!$K$2 -> 1215408.7 | I3: =SUM(G3:H3)/1000000 -> 9.7701662 | J3: =I3/D3 -> 1.0811285 | L3: =E3+E3*30*Validate_2020!G2/100 -> 9.5433336 | M3: =L3/E3 -> 1.114936
A4: Agropastoral | B4: =[18]Agpastoral_Zebu_2020!$K$2 -> 3685141 | C4: =[19]Agpastoral_Boran_2020!$K$2 -> 277376.2 | D4: =SUM(B4:C4)/1000000 -> 3.9625172 | E4: =Herd_decision_tree!E14*Herd_decision_tree!$E$49 -> 5.5401815 | G4: =[20]Agpastoral_Zebu_2050!$K$2 -> 6488770.1 | H4: =[21]Agpastoral_Boran_2050!$K$2 -> 488402.05 | I4: =SUM(G4:H4)/1000000 -> 6.9771722 | J4: =I4/D4 -> 1.7607929 | L4: =E4+E4*30*Validate_2020!G3/100 -> 10.185694 | M4: =L4/E4 -> 1.8385127
A5: Mixed | B5: =[22]Mixed_Zebu_2020!$K$2 -> 298374.72 | C5: =[23]Mixed_Boran_2020!$K$2 -> 25945.627 | D5: =SUM(B5:C5)/1000000 -> 0.32432034 | E5: =Herd_decision_tree!E18*Herd_decision_tree!$E$49 -> 0.9530402 | G5: =[24]Mixed_Zebu_2050!$K$2 -> 404262.59 | H5: =[25]Mixed_Boran_2050!$K$2 -> 35153.27 | I5: =SUM(G5:H5)/1000000 -> 0.43941586 | J5: =I5/D5 -> 1.3548822 | L5: =E5+E5*30*Validate_2020!G4/100 -> 1.3403335 | M5: =L5/E5 -> 1.4063766
A6: Cow-calf | B6: =[26]Cowcalf_Boran_2020!$K$2 -> 1184753.3 | C6: =[27]Cowcalf_Exotic_2020!$K$2 -> 985977.36 | D6: =SUM(B6:C6)/1000000 -> 2.1707307 | E6: =Herd_decision_tree!E29*Herd_decision_tree!$E$49 -> 0.84668818 | G6: =[28]Cowcalf_Boran_2050!$K$2 -> 1806208.7 | H6: =[29]Cowcalf_Exotic_2050!$K$2 -> 1503165.9 | I6: =SUM(G6:H6)/1000000 -> 3.3093746 | J6: =I6/D6 -> 1.5245441 | L6: =E6+E6*30*Validate_2020!G5/100 -> 1.1101523 | M6: =L6/E6 -> 1.3111702
A7: Finisher | B7: =[30]Finisher_Boran_2020!$K$2 -> 26321.876 | C7: =[31]Finisher_Exotic_2020!$K$2 -> 12386.765 | D7: =SUM(B7:C7)/1000000 -> 0.038708641 | E7: =Herd_decision_tree!E25*Herd_decision_tree!$E$49 -> 0.71805364 | G7: =[32]Finisher_Boran_2050!$K$2 -> 918345.46 | H7: =[33]Finisher_Exotic_2050!$K$2 -> 432162.57 | I7: =SUM(G7:H7)/1000000 -> 1.350508 | J7: =I7/D7 -> 34.889058 | L7: =E7+E7*30*Validate_2020!G6/100 -> 19.344343 | M7: =L7/E7 -> 26.93997
D8: =SUM(D3:D7) -> 15.533284 | E8: =SUM(E3:E7) -> 16.617498 | G8: =SUM(G3:G7) -> 18172344 | H8: =SUM(H3:H7) -> 3674292.5 | I8: =SUM(I3:I7) -> 21.846637 | J8: =I8/D8 -> 1.4064403 | L8: =SUM(L3:L7) -> 41.523857 | M8: =L8/E8 -> 2.4988032

Sheet NPP
A1: Year | C1: Arid | D1: Semi-arid | E1: Humid
A2: Land areas (ha) | B2: GRASSLAND | C2: =[34]ZS_Grassland_Arid!$D$2*L15 -> 7105919 | D2: =[35]ZS_Grassland_SArid!$D$2*L15 -> 4556839.6 | E2: =[36]ZS_Grassland_Humid!$E$2*L15 -> 2262153.4
B3: CROPLAND | C3: =[37]ZS_Cropland_Arid!$D$2*L15 -> 18395.02 | D3: =[38]ZS_Cropland_SArid!$D$2*L15 -> 686372.96 | E3: =[39]ZS_Cropland_Humid!$E$2*L15 -> 950603.99
B4: SHRUBLAND | C4: =[40]ZS_Shrubland_Arid!$D$2*L15 -> 9755293.3 | D4: =[41]ZS_Shrubland_SArid!$D$2*L15 -> 12549722 | E4: =[42]ZS_Shrubland_Humid!$E$2*L15 -> 2223118.4
B6: NPP (kg C/m2/yr)
A7: 2020 | B7: NPP - Grassland | C7: =[43]NPP_2020_GRASS_Arid!$E$2 -> 0.33293323 | D7: =[44]NPP_2020_GRASS_SArid!$E$2 -> 0.48080803 | E7: =[45]filtered!$F$2 -> 0.88607168
B8: NPP - Cropland | C8: =[46]NPP_2020_CROP_Arid!$E$2 -> 0.97599039 | D8: =[47]NPP_2020_CROP_SArid!$E$2 -> 0.71416469 | E8: =[48]filtered!$F$2 -> 1.0193613
B9: NPP - Shrubland | C9: =[49]NPP_2020_SHRUB_Arid!$E$2 -> 0.20100553 | D9: =[50]NPP_2020_SHRUB_SArid!$E$2 -> 0.48842844 | E9: =[51]filtered!$F$2 -> 0.92845073
A11: 2050 R4 | B11: NPP - Grassland | C11: =[52]NPP_2050_R4_GRASS_Arid!$E$2 -> 0.36084904 | D11: =[53]NPP_2050_R4_GRASS_SArid!$E$2 -> 0.51075241 | E11: =[54]filtered!$F$2 -> 0.90483098 | F11: =C11/C7 -> 1.0838481 | G11: =D11/D7 -> 1.0622793 | H11: =E11/E7 -> 1.0211713
B12: NPP - Cropland | C12: =[55]NPP_2050_R4_CROP_Arid!$E$2 -> 1.0384816 | D12: =[56]NPP_2050_R4_CROP_SArid!$E$2 -> 0.72447114 | E12: =[57]filtered!$F$2 -> 0.98649142 | F12: =C12/C8 -> 1.0640286 | G12: =D12/D8 -> 1.0144315 | H12: =E12/E8 -> 0.96775447
B13: NPP - Shrubland | C13: =[58]NPP_2050_R4_SHRUB_Arid!$E$2 -> 0.21776708 | D13: =[59]NPP_2050_R4_SHRUB_SArid!$E$2 -> 0.51075241 | E13: =[60]filtered!$F$2 -> 0.90483098 | F13: =C13/C9 -> 1.0833885 | G13: =D13/D9 -> 1.0457057 | H13: =E13/E9 -> 0.97456004
A15: 2050 R8 | B15: NPP - Grassland | C15: =[61]NPP_2050_R8_GRASS_Arid!$E$2 -> 0.38422689 | D15: =[62]NPP_2050_R8_GRASS_SArid!$E$2 -> 0.51337712 | E15: =[63]filtered!$F$2 -> 0.8845746 | F15: =C15/C7 -> 1.1540659 | G15: =D15/D7 -> 1.0677382 | H15: =E15/E7 -> 0.99831043 | K15: 2020 - ha/pixel | L15: =35.105 -> 35.105
B16: NPP - Cropland | C16: =[64]NPP_2050_R8_CROP_Arid!$E$2 -> 1.1053285 | D16: =[65]NPP_2050_R8_CROP_SArid!$E$2 -> 0.80695681 | E16: =[66]filtered!$F$2 -> 1.0242826 | F16: =C16/C8 -> 1.1325199 | G16: =D16/D8 -> 1.129931 | H16: =E16/E12 -> 1.0383086 | K16: 2050 - ha/pixel | L16: =L15 -> 35.105
B17: NPP - Shrubland | C17: =[67]NPP_2050_R8_SHRUB_Arid!$E$2 -> 0.23131988 | D17: =[68]NPP_2050_R8_SHRUB_SArid!$E$2 -> 0.51046847 | E17: =[69]filtered!$F$2 -> 0.93416976 | F17: =C17/C9 -> 1.1508135 | G17: =D17/D9 -> 1.0451244 | H17: =E17/E9 -> 1.0061598
A20: 2020 | B20: BIOM GRASS Supply (MT/ha/yr) | C20: =10000*(1/1000)*(C2*C7+C3*C8*[70]Raster_logic!$I$95+C4*C9*[70]Raster_logic!$I$96)*(1/[70]Raster_logic!$I$89)*[70]Raster_logic!$I$90*[70]Raster_logic!$I$91/1000000 -> 11.151655 | D20: =10000*(1/1000)*(D2*D7+D3*D8*[70]Raster_logic!$I$95+D4*D9*[70]Raster_logic!$I$96)*(1/[70]Raster_logic!$I$89)*[70]Raster_logic!$I$90*[70]Raster_logic!$I$91/1000000 -> 16.992868 | E20: =10000*(1/1000)*(E2*E7+E3*E8*[70]Raster_logic!$I$95+E4*E9*[70]Raster_logic!$I$96)*(1/[70]Raster_logic!$I$89)*[70]Raster_logic!$I$90*[70]Raster_logic!$I$91/1000000 -> 11.1632
B21: BIOM CROP Supply (MT/ha/yr) | C21: =10000*(1/1000)*(C3*C8*[70]Raster_logic!$I$102)*(1/[70]Raster_logic!$I$98)*[70]Raster_logic!$I$99*[70]Raster_logic!$I$100/1000000 -> 0.062836769 | D21: =10000*(1/1000)*(D3*D8*[70]Raster_logic!$I$102)*(1/[70]Raster_logic!$I$98)*[70]Raster_logic!$I$99*[70]Raster_logic!$I$100/1000000 -> 1.7156417 | E21: =10000*(1/1000)*(E3*E8*[70]Raster_logic!$I$102)*(1/[70]Raster_logic!$I$98)*[70]Raster_logic!$I$99*[70]Raster_logic!$I$100/1000000 -> 3.3915311
B22: BIOM Total (MT/ha/yr) | C22: =SUM(C20:C21) -> 11.214492 | D22: =SUM(D20:D21) -> 18.70851 | E22: =SUM(E20:E21) -> 14.554731
A24: 2050 R4 | B24: =B20 -> BIOM GRASS Supply (MT/ha/yr) | C24: =10000*(1/1000)*(C2*C11+C3*C12*[70]Raster_logic!$I$95+C4*C13*[70]Raster_logic!$I$96)*(1/[70]Raster_logic!$I$89)*[70]Raster_logic!$I$90*[70]Raster_logic!$I$91/1000000 -> 12.084999 | D24: =10000*(1/1000)*(D2*D11+D3*D12*[70]Raster_logic!$I$95+D4*D13*[70]Raster_logic!$I$96)*(1/[70]Raster_logic!$I$89)*[70]Raster_logic!$I$90*[70]Raster_logic!$I$91/1000000 -> 17.879421 | E24: =10000*(1/1000)*(E2*E11+E3*E12*[70]Raster_logic!$I$95+E4*E13*[70]Raster_logic!$I$96)*(1/[70]Raster_logic!$I$89)*[70]Raster_logic!$I$90*[70]Raster_logic!$I$91/1000000 -> 11.20139 | F24: =C24/C20 -> 1.0836955 | G24: =D24/D20 -> 1.0521721 | H24: =E24/E20 -> 1.0034211
B25: =B21 -> BIOM CROP Supply (MT/ha/yr) | C25: =10000*(1/1000)*(C3*C12*[70]Raster_logic!$I$102)*(1/[70]Raster_logic!$I$98)*[70]Raster_logic!$I$99*[70]Raster_logic!$I$100/1000000 -> 0.066860117 | D25: =10000*(1/1000)*(D3*D12*[70]Raster_logic!$I$102)*(1/[70]Raster_logic!$I$98)*[70]Raster_logic!$I$99*[70]Raster_logic!$I$100/1000000 -> 1.7404009 | E25: =10000*(1/1000)*(E3*E12*[70]Raster_logic!$I$102)*(1/[70]Raster_logic!$I$98)*[70]Raster_logic!$I$99*[70]Raster_logic!$I$100/1000000 -> 3.2821694 | F25: =C25/C21 -> 1.0640286 | G25: =D25/D21 -> 1.0144315 | H25: =E25/E21 -> 0.96775447
B26: =B22 -> BIOM Total (MT/ha/yr) | C26: =SUM(C24:C25) -> 12.151859 | D26: =SUM(D24:D25) -> 19.619822 | E26: =SUM(E24:E25) -> 14.48356 | F26: =C26/C22 -> 1.0835853 | G26: =D26/D22 -> 1.0487111 | H26: =E26/E22 -> 0.99511006
A28: 2050 R8 | B28: =B24 -> BIOM GRASS Supply (MT/ha/yr) | C28: =10000*(1/1000)*(C2*C15+C3*C16*[70]Raster_logic!$I$95+C4*C17*[70]Raster_logic!$I$96)*(1/[70]Raster_logic!$I$89)*[70]Raster_logic!$I$90*[70]Raster_logic!$I91/1000000 -> 12.860267 | D28: =10000*(1/1000)*(D2*D15+D3*D16*[70]Raster_logic!$I$95+D4*D17*[70]Raster_logic!$I$96)*(1/[70]Raster_logic!$I$89)*[70]Raster_logic!$I$90*[70]Raster_logic!$I91/1000000 -> 17.984656 | E28: =10000*(1/1000)*(E2*E15+E3*E16*[70]Raster_logic!$I$95+E4*E17*[70]Raster_logic!$I$96)*(1/[70]Raster_logic!$I$89)*[70]Raster_logic!$I$90*[70]Raster_logic!$I91/1000000 -> 11.174823 | F28: =C28/C20 -> 1.153216 | G28: =D28/D20 -> 1.0583649 | H28: =E28/E20 -> 1.0010412
B29: =B25 -> BIOM CROP Supply (MT/ha/yr) | C29: =10000*(1/1000)*(C3*C16*[70]Raster_logic!$I$102)*(1/[70]Raster_logic!$I$98)*[70]Raster_logic!$I$99*[70]Raster_logic!$I$100/1000000 -> 0.071163889 | D29: =10000*(1/1000)*(D3*D16*[70]Raster_logic!$I$102)*(1/[70]Raster_logic!$I$98)*[70]Raster_logic!$I$99*[70]Raster_logic!$I$100/1000000 -> 1.9385567 | E29: =10000*(1/1000)*(E3*E16*[70]Raster_logic!$I$102)*(1/[70]Raster_logic!$I$98)*[70]Raster_logic!$I$99*[70]Raster_logic!$I$100/1000000 -> 3.4079048 | F29: =C29/C21 -> 1.1325199 | G29: =D29/D21 -> 1.129931 | H29: =E29/E21 -> 1.0048278
B30: =B26 -> BIOM Total (MT/ha/yr) | C30: =SUM(C28:C29) -> 12.931431 | D30: =SUM(D28:D29) -> 19.923213 | E30: =SUM(E28:E29) -> 14.582728 | F30: =C30/C22 -> 1.1531 | G30: =D30/D22 -> 1.0649278 | H30: =E30/E22 -> 1.0019235

Sheet Carrying_Capacity
A1: Year | C1: Arid | D1: Semi-arid | E1: Humid | H1: Mean LW -- beef cattle (kg) -- Baseline | I1: 195.2496
A2: 2020 | B2: Pastoral | C2: =Herd_decision_tree!B10 -> 4.2982452 | D2: =Herd_decision_tree!C10 -> 4.2319458 | E2: 0 | H2: Mean LW -- beef cattle (kg) -- Low-end | I2: 193.39196
B3: Agropastoral | C3: 0 | D3: =Herd_decision_tree!C14 -> 3.0046236 | E3: =Herd_decision_tree!D14 -> 2.5165651 | H3: Mean LW -- beef cattle (kg) -- High-end | I3: 197.10724
B4: Mixed | C4: 0 | D4: 0 | E4: =Herd_decision_tree!D18 -> 0.94977299 | H4: Mean LW -- dairy cattle (kg) | I4: 201
B5: Cowcalf | C5: =Herd_decision_tree!B29 -> 0.064335272 | D5: =Herd_decision_tree!C29 -> 0.29733782 | E5: =Herd_decision_tree!D29 -> 0.48211248 | H5: Mean LW -- sheep (kg) | I5: 28
B6: Finisher | C6: =Herd_decision_tree!B25 -> 0.20502322 | D6: =Herd_decision_tree!C25 -> 0.27325052 | E6: =Herd_decision_tree!D25 -> 0.23731827 | H6: FRAC Fed -- Arid | I6: =0.06 -> 0.06
B7: Dairy | C7: =Herd_decision_tree!B35 -> 0.030271362 | D7: =Herd_decision_tree!C35 -> 1.4765741 | E7: =Herd_decision_tree!D35 -> 6.385378 | H7: FRAC Fed -- Semi-arid | I7: =0.0825 -> 0.0825
B8: Sheep | C8: =Herd_decision_tree!B5 -> 11.794047 | D8: =Herd_decision_tree!C5 -> 9.6481198 | E8: =Herd_decision_tree!D5 -> 9.0810137 | H8: FRAC Fed -- Humid/Subhumid | I8: 0.12
H9: FRAC DMI as BW | I9: =0.02 -> 0.02
B10: Total weight - Beef (kg) - BL | C10: =SUM(C2:C6)*$I1*1000000 -> 8.9182278e+08 | D10: =SUM(D2:D6)*$I1*1000000 -> 1.5243444e+09 | E10: =SUM(E2:E6)*$I1*1000000 -> 8.1726968e+08
B11: Total weight - Beef (kg) - WC | C11: =SUM(C2:C6)*$I2*1000000 -> 8.8333783e+08 | D11: =SUM(D2:D6)*$I2*1000000 -> 1.5098416e+09 | E11: =SUM(E2:E6)*$I2*1000000 -> 8.0949404e+08
B12: Total weight - Beef (kg) - BC | C12: =SUM(C2:C6)*$I3*1000000 -> 9.0030773e+08 | D12: =SUM(D2:D6)*$I3*1000000 -> 1.5388473e+09 | E12: =SUM(E2:E6)*$I3*1000000 -> 8.2504532e+08
B13: Total weight - Dairy (kg) | C13: =C7*$I$4*1000000 -> 6084543.8 | D13: =D7*$I$4*1000000 -> 2.9679139e+08 | E13: =E7*$I$4*1000000 -> 1.283461e+09
B14: Total weight - Sheep (kg) | C14: =C8*$I$5*1000000 -> 3.3023333e+08 | D14: =D8*$I$5*1000000 -> 2.7014736e+08 | E14: =E8*$I$5*1000000 -> 2.5426838e+08
B16: Biomass demand (MT/yr) - BL | C16: =365*(C10+C$13+C$14)*(1-$I$6)*($I$9)/1000/1000000 -> 8.4275012 | D16: =365*(D10+D$13+D$14)*(1-$I$7)*($I$9)/1000/1000000 -> 14.006892 | E16: =365*(E10+E$13+E$14)*(1-$I$8)*($I$9)/1000/1000000 -> 15.128514
B17: Biomass demand (MT/yr) - WC | C17: =365*(C11+C$13+C$14)*(1-$I$6)*($I$9)/1000/1000000 -> 8.3692774 | D17: =365*(D11+D$13+D$14)*(1-$I$7)*($I$9)/1000/1000000 -> 13.909755 | E17: =365*(E11+E$13+E$14)*(1-$I$8)*($I$9)/1000/1000000 -> 15.078563
B18: Biomass demand (MT/yr) - BC | C18: =365*(C12+C$13+C$14)*(1-$I$6)*($I$9)/1000/1000000 -> 8.4857249 | D18: =365*(D12+D$13+D$14)*(1-$I$7)*($I$9)/1000/1000000 -> 14.104028 | E18: =365*(E12+E$13+E$14)*(1-$I$8)*($I$9)/1000/1000000 -> 15.178465
B20: Biomass supply (MT/yr) | C20: =NPP!C22 -> 11.214492 | D20: =NPP!D22 -> 18.70851 | E20: =NPP!E22 -> 14.554731
B22: Carrying capacity (S/D) - BL | C22: =C$20/C16 -> 1.3307019 | D22: =D$20/D16 -> 1.3356646 | E22: =E$20/E16 -> 0.96207277
B23: Carrying capacity (S/D) - WC | C23: =C$20/C17 -> 1.3399594 | D23: =D$20/D17 -> 1.344992 | E23: =E$20/E17 -> 0.96525983
B24: Carrying capacity (S/D) - BC | C24: =C$20/C18 -> 1.3215715 | D24: =D$20/D18 -> 1.3264657 | E24: =E$20/E18 -> 0.95890669
B26: 2050
B27: Animal populations (M hd)
B28: Pastoral | C28: =C2+C2*30*Validate_2020!$G2/100 -> 4.7922684 | D28: =D2+D2*30*Validate_2020!$G2/100 -> 4.7183488 | E28: =E2+E2*30*Validate_2020!$G2/100 -> 0
B29: Agropastoral | C29: =C3+C3*30*Validate_2020!$G3/100 -> 0 | D29: =D3+D3*30*Validate_2020!$G3/100 -> 5.5240388 | E29: =E3+E3*30*Validate_2020!$G3/100 -> 4.6267369
B30: Humid/subhumid | C30: =C4+C4*30*Validate_2020!$G4/100 -> 0 | D30: =D4+D4*30*Validate_2020!$G4/100 -> 0 | E30: =E4+E4*30*Validate_2020!$G4/100 -> 1.3357386
B31: Cowcalf | C31: =C5+C5*30*Validate_2020!$G5/100 -> 0.084354492 | D31: =D5+D5*30*Validate_2020!$G5/100 -> 0.38986049 | E31: =E5+E5*30*Validate_2020!$G5/100 -> 0.63213152
B32: Finisher | C32: =C6+C6*30*Validate_2020!$G6/100 -> 5.5233194 | D32: =D6+D6*30*Validate_2020!$G6/100 -> 7.3613607 | E32: =E6+E6*30*Validate_2020!$G6/100 -> 6.3933469
B33: Dairy | C33: =C7+C7*30*Validate_2020!G8/100 -> 0.030271362 | D33: =D7+D7*30*Validate_2020!H8/100 -> 1.5191844 | E33: =E7+E7*30*Validate_2020!I8/100 -> 6.385378
B34: Sheep | C34: =C8+C8*30*1.35*Validate_2020!$G7/100 -> 22.673264 | D34: =D8+D8*30*1*Validate_2020!$G7/100 -> 16.240522 | E34: =E8+E8*30*0.65*Validate_2020!$G7/100 -> 13.114204
B36: Total animal weights (kg), by species
A37: . | B37: Beef - Baseline | C37: =SUM(C$28:C$32)*$I1*1000000 -> 2.0305846e+09 | D37: =SUM(D$28:D$32)*$I1*1000000 -> 3.5132449e+09 | E37: =SUM(E$28:E$32)*$I1*1000000 -> 2.5358928e+09
B38: Beef - Low-end | C38: =SUM(C$28:C$32)*$I2*1000000 -> 2.0112652e+09 | D38: =SUM(D$28:D$32)*$I2*1000000 -> 3.4798193e+09 | E38: =SUM(E$28:E$32)*$I2*1000000 -> 2.5117659e+09
B39: Beef - High-end | C39: =SUM(C$28:C$32)*$I3*1000000 -> 2.0499039e+09 | D39: =SUM(D$28:D$32)*$I3*1000000 -> 3.5466705e+09 | E39: =SUM(E$28:E$32)*$I3*1000000 -> 2.5600197e+09
B40: Dairy | C40: =C33*$I4*1000000 -> 6084543.8 | D40: =D33*$I4*1000000 -> 3.0535607e+08 | E40: =E33*$I4*1000000 -> 1.283461e+09
B41: Sheep | C41: =C34*$I5*1000000 -> 6.3485139e+08 | D41: =D34*$I5*1000000 -> 4.5473461e+08 | E41: =E34*$I5*1000000 -> 3.671977e+08
B43: RCP 4.5
B44: Biomass demand (MT/ha/yr)
B45: BL | C45: =365*(C37+C$40+C$41)*(1-$I$6)*($I$9)/1000/1000000 -> 18.331974 | D45: =365*(D37+D$40+D$41)*(1-$I$7)*($I$9)/1000/1000000 -> 28.621733 | E45: =365*(E37+E$40+E$41)*(1-$I$8)*($I$9)/1000/1000000 -> 26.894407
B46: WC | C46: =365*(C38+C$40+C$41)*(1-$I$6)*($I$9)/1000/1000000 -> 18.199405 | D46: =365*(D38+D$40+D$41)*(1-$I$7)*($I$9)/1000/1000000 -> 28.397857 | E46: =365*(E38+E$40+E$41)*(1-$I$8)*($I$9)/1000/1000000 -> 26.739415
...

Sheet Beef_population_to_GIS
A1: breed | B1: farm.type | C1: aez | D1: cohort | E1: scenario | F1: population.M.hd
A2: zebu | B2: pastoral | C2: arid | D2: male.finisher | E2: baseline | F2: =Herd_decision_tree!B11 -> 3.7635435
A3: zebu | B3: pastoral | C3: arid | D3: female.finisher | E3: baseline | F3: =F2 -> 3.7635435
A4: zebu | B4: pastoral | C4: arid | D4: female.breeder | E4: baseline | F4: =F3 -> 3.7635435
A5: zebu | B5: pastoral | C5: semi.arid | D5: =D2 -> male.finisher | E5: baseline | F5: =Herd_decision_tree!C11 -> 3.7054917
A6: zebu | B6: pastoral | C6: semi.arid | D6: =D3 -> female.finisher | E6: baseline | F6: =F5 -> 3.7054917
A7: zebu | B7: pastoral | C7: semi.arid | D7: =D4 -> female.breeder | E7: baseline | F7: =F6 -> 3.7054917
A8: boran | B8: pastoral | C8: arid | D8: =D5 -> male.finisher | E8: baseline | F8: =Herd_decision_tree!B12 -> 0.5347017
A9: boran | B9: pastoral | C9: arid | D9: =D6 -> female.finisher | E9: baseline | F9: =F8 -> 0.5347017
A10: boran | B10: pastoral | C10: arid | D10: =D7 -> female.breeder | E10: baseline | F10: =F9 -> 0.5347017
A11: boran | B11: pastoral | C11: semi.arid | D11: =D8 -> male.finisher | E11: baseline | F11: =Herd_decision_tree!C12 -> 0.52645406
A12: boran | B12: pastoral | C12: semi.arid | D12: =D9 -> female.finisher | E12: baseline | F12: =F11 -> 0.52645406
A13: boran | B13: pastoral | C13: semi.arid | D13: =D10 -> female.breeder | E13: baseline | F13: =F12 -> 0.52645406
A14: zebu | B14: agro-pastoral | C14: semi.arid | D14: =D11 -> male.finisher | E14: baseline | F14: =Herd_decision_tree!C15 -> 2.7943
A15: zebu | B15: agro-pastoral | C15: semi.arid | D15: =D12 -> female.finisher | E15: baseline | F15: =F14 -> 2.7943
A16: zebu | B16: agro-pastoral | C16: semi.arid | D16: =D13 -> female.breeder | E16: baseline | F16: =F15 -> 2.7943
A17: zebu | B17: agro-pastoral | C17: humid.subhumid | D17: =D14 -> male.finisher | E17: baseline | F17: =Herd_decision_tree!D15 -> 2.3404055
A18: zebu | B18: agro-pastoral | C18: humid.subhumid | D18: =D15 -> female.finisher | E18: baseline | F18: =F17 -> 2.3404055
A19: zebu | B19: agro-pastoral | C19: humid.subhumid | D19: =D16 -> female.breeder | E19: baseline | F19: =F18 -> 2.3404055
A20: boran | B20: agro-pastoral | C20: semi.arid | D20: =D17 -> male.finisher | E20: baseline | F20: =Herd_decision_tree!C16 -> 0.21032365
A21: boran | B21: agro-pastoral | C21: semi.arid | D21: =D18 -> female.finisher | E21: baseline | F21: =F20 -> 0.21032365
A22: boran | B22: agro-pastoral | C22: semi.arid | D22: =D19 -> female.breeder | E22: baseline | F22: =F21 -> 0.21032365
A23: boran | B23: agro-pastoral | C23: humid.subhumid | D23: =D20 -> male.finisher | E23: baseline | F23: =Herd_decision_tree!D16 -> 0.17615955
A24: boran | B24: agro-pastoral | C24: humid.subhumid | D24: =D21 -> female.finisher | E24: baseline | F24: =F23 -> 0.17615955
A25: boran | B25: agro-pastoral | C25: humid.subhumid | D25: =D22 -> female.breeder | E25: baseline | F25: =F24 -> 0.17615955
A26: zebu | B26: mixed | C26: humid.subhumid | D26: =D23 -> male.finisher | E26: baseline | F26: =Herd_decision_tree!D19 -> 0.87379115
A27: zebu | B27: mixed | C27: humid.subhumid | D27: =D24 -> female.finisher | E27: baseline | F27: =F26 -> 0.87379115
A28: zebu | B28: mixed | C28: humid.subhumid | D28: =D25 -> female.breeder | E28: baseline | F28: =F27 -> 0.87379115
A29: boran | B29: mixed | C29: humid.subhumid | D29: =D26 -> male.finisher | E29: baseline | F29: =Herd_decision_tree!D20 -> 0.075981839
A30: boran | B30: mixed | C30: humid.subhumid | D30: =D27 -> female.finisher | E30: baseline | F30: =F29 -> 0.075981839
A31: boran | B31: mixed | C31: humid.subhumid | D31: =D28 -> female.breeder | E31: baseline | F31: =F30 -> 0.075981839
A32: boran | B32: cow-calf | C32: arid | D32: =D29 -> male.finisher | E32: baseline | F32: =Herd_decision_tree!B30 -> 0.043747985
A33: boran | B33: cow-calf | C33: arid | D33: =D30 -> female.finisher | E33: baseline | F33: =F32 -> 0.043747985
A34: boran | B34: cow-calf | C34: arid | D34: =D31 -> female.breeder | E34: baseline | F34: =F33 -> 0.043747985
A35: boran | B35: cow-calf | C35: semi.arid | D35: =D32 -> male.finisher | E35: baseline | F35: =Herd_decision_tree!C30 -> 0.20218972
A36: boran | B36: cow-calf | C36: semi.arid | D36: =D33 -> female.finisher | E36: baseline | F36: =F35 -> 0.20218972
A37: boran | B37: cow-calf | C37: semi.arid | D37: =D34 -> female.breeder | E37: baseline | F37: =F36 -> 0.20218972
A38: boran | B38: cow-calf | C38: humid.subhumid | D38: =D35 -> male.finisher | E38: baseline | F38: =Herd_decision_tree!D30 -> 0.32783648
A39: boran | B39: cow-calf | C39: humid.subhumid | D39: =D36 -> female.finisher | E39: baseline | F39: =F38 -> 0.32783648
A40: boran | B40: cow-calf | C40: humid.subhumid | D40: =D37 -> female.breeder | E40: baseline | F40: =F39 -> 0.32783648
...
